Traceback (most recent call last):
  File "/home/haz19024/miniconda3/lib/python3.11/site-packages/jupyter_core/utils/__init__.py", line 154, in wrapped
    asyncio.get_running_loop()
RuntimeError: no running event loop

During handling of the above exception, another exception occurred:

Traceback (most recent call last):
  File "/home/haz19024/miniconda3/lib/python3.11/site-packages/jupyter_cache/executors/utils.py", line 58, in single_nb_execution
    executenb(
  File "/home/haz19024/miniconda3/lib/python3.11/site-packages/nbclient/client.py", line 1319, in execute
    return NotebookClient(nb=nb, resources=resources, km=km, **kwargs).execute()
           ^^^^^^^^^^^^^^^^^^^^^^^^^^^^^^^^^^^^^^^^^^^^^^^^^^^^^^^^^^^^^^^^^^^^^
  File "/home/haz19024/miniconda3/lib/python3.11/site-packages/jupyter_core/utils/__init__.py", line 158, in wrapped
    return loop.run_until_complete(inner)
           ^^^^^^^^^^^^^^^^^^^^^^^^^^^^^^
  File "/home/haz19024/miniconda3/lib/python3.11/asyncio/base_events.py", line 654, in run_until_complete
    return future.result()
           ^^^^^^^^^^^^^^^
  File "/home/haz19024/miniconda3/lib/python3.11/site-packages/nbclient/client.py", line 709, in async_execute
    await self.async_execute_cell(
  File "/home/haz19024/miniconda3/lib/python3.11/site-packages/nbclient/client.py", line 1062, in async_execute_cell
    await self._check_raise_for_error(cell, cell_index, exec_reply)
  File "/home/haz19024/miniconda3/lib/python3.11/site-packages/nbclient/client.py", line 918, in _check_raise_for_error
    raise CellExecutionError.from_cell_and_msg(cell, exec_reply_content)
nbclient.exceptions.CellExecutionError: An error occurred while executing the following cell:
------------------
import scistree2 as s2
import numpy as np 

probs = np.array([[0.01, 0.6, 0.08, 0.8, 0.7],
                 [0.8, 0.02, 0.7, 0.01, 0.3],
                 [0.02, 0.8, 0.02, 0.8, 0.9],
                 [0.9, 0.9, 0.8, 0.8, 0.02],
                 [0.01, 0.8, 0.01, 0.8, 0.9],
                 [0.05, 0.02, 0.7, 0.05, 0.9]]) 
cell_names = ['cell1', 'cell2', 'cell3', 'cell4', 'cell5']
site_names = ['snp1', 'snp2', 'snp3', 'snp4', 'snp5', 'snp6']
gp = s2.probability.from_probs(probs, cell_names, site_names)
print(gp)
------------------


[31m---------------------------------------------------------------------------[39m
[31mModuleNotFoundError[39m                       Traceback (most recent call last)
[36mCell[39m[36m [39m[32mIn[1][39m[32m, line 1[39m
[32m----> [39m[32m1[39m [38;5;28;01mimport[39;00m[38;5;250m [39m[34;01mscistree2[39;00m[38;5;250m [39m[38;5;28;01mas[39;00m[38;5;250m [39m[34;01ms2[39;00m
[32m      2[39m [38;5;28;01mimport[39;00m[38;5;250m [39m[34;01mnumpy[39;00m[38;5;250m [39m[38;5;28;01mas[39;00m[38;5;250m [39m[34;01mnp[39;00m 
[32m      4[39m probs = np.array([[[32m0.01[39m, [32m0.6[39m, [32m0.08[39m, [32m0.8[39m, [32m0.7[39m],
[32m      5[39m                  [[32m0.8[39m, [32m0.02[39m, [32m0.7[39m, [32m0.01[39m, [32m0.3[39m],
[32m      6[39m                  [[32m0.02[39m, [32m0.8[39m, [32m0.02[39m, [32m0.8[39m, [32m0.9[39m],
[32m      7[39m                  [[32m0.9[39m, [32m0.9[39m, [32m0.8[39m, [32m0.8[39m, [32m0.02[39m],
[32m      8[39m                  [[32m0.01[39m, [32m0.8[39m, [32m0.01[39m, [32m0.8[39m, [32m0.9[39m],
[32m      9[39m                  [[32m0.05[39m, [32m0.02[39m, [32m0.7[39m, [32m0.05[39m, [32m0.9[39m]]) 

[31mModuleNotFoundError[39m: No module named 'scistree2'

